Workbook

Sheet Istruzioni
A1: Registro annuale compensi da lavoro autonomo occasionale
A2: Lumen & Ledger — template, licenza CC BY 4.0. Nessuna macro, nessun collegamento esterno. Regole verificate il 31/10/2026.
A4: A COSA SERVE
A5: Tenere in un unico posto tutte le ricevute dell'anno e sapere in ogni momento: quanto hai incassato rispetto alla soglia INPS di 5.000 €,
A6: quante ritenute d'acconto ti sono state trattenute (da ritrovare nelle Certificazioni Uniche e da scomputare in dichiarazione), chi deve ancora pagarti.
A8: COME SI USA
A9: 1. Foglio 'Ricevute': una riga per ricevuta. Compila solo le celle gialle. Le righe di esempio sono fittizie: cancellale o sovrascrivile.
A10: 2. Tipo committente: 'Sostituto d'imposta' (impresa, professionista, ente: trattiene il 20%) oppure 'Privato' (nessuna ritenuta).
A11: 3. Quando vieni pagato, inserisci data e importo incassato: l'anno di riferimento diventa quello dell'incasso.
A12: 4. Foglio 'Riepilogo': scegli l'anno in B2. Vedi totale, distanza dalla soglia 5.000 €, ritenute, crediti aperti, CU da ricevere, mesi e committenti.
A13: 5. Foglio 'Parametri': aliquota, bollo e soglie usati dalle formule. Se la normativa cambia, aggiorni solo li'.
A14: Per creare e stampare le ricevute: generatore gratuito https://lumen-ledger.github.io/it/ricevuta-prestazione-occasionale/
... A37: Questo foglio e' informazione generale e strumento di calcolo, non consulenza fiscale o legale. Verifica il tuo caso con un professionista o un CAF.

Sheet Ricevute
A1: Data ricevuta | B1: N. | C1: Committente | D1: Tipo committente | E1: Descrizione prestazione | F1: Compenso € | G1: Rimborso spese € | H1: Bollo addebitato al committente? | I1: Lordo € | J1: Ritenuta subita € | K1: Bollo 2 € dovuto? | L1: Netto atteso € | M1: Data incasso | N1: Importo incassato € | O1: Da incassare € | P1: CU ricevuta? | Q1: Note | R1: Anno rif. | S1: Mese rif.
A2: 46091 | B2: 1 | C2: Esempio Srl | D2: Sostituto d'imposta | E2: Traduzione catalogo | F2: 500 | G2: 0 | H2: No | I2: =IF(OR(F2<>"",G2<>""),ROUND(N(F2)+N(G2),2),"") | J2: =IF(I2="","",IF(D2="Sostituto d'imposta",ROUND(I2*Parametri!$B$2,2),0)) | K2: =IF(I2="","",IF(I2>Parametri!$B$4,"Si","No")) | L2: =IF(I2="","",I2-J2+IF(AND(K2="Si",H2="Si"),Parametri!$B$3,0)) | M2: 46112 | N2: 400 | O2: =IF(L2="","",ROUND(L2-N(N2),2)) | P2: Si | R2: =IF(I2="","",IF(M2<>"",YEAR(M2),IF(A2<>"",YEAR(A2),""))) | S2: =IF(I2="","",IF(M2<>"",MONTH(M2),IF(A2<>"",MONTH(A2),"")))
A3: 46175 | B3: 2 | C3: Mario Esempio | D3: Privato | E3: Lezioni private | F3: 300 | G3: 0 | H3: No | I3: =IF(OR(F3<>"",G3<>""),ROUND(N(F3)+N(G3),2),"") | J3: =IF(I3="","",IF(D3="Sostituto d'imposta",ROUND(I3*Parametri!$B$2,2),0)) | K3: =IF(I3="","",IF(I3>Parametri!$B$4,"Si","No")) | L3: =IF(I3="","",I3-J3+IF(AND(K3="Si",H3="Si"),Parametri!$B$3,0)) | M3: 46175 | N3: 300 | O3: =IF(L3="","",ROUND(L3-N(N3),2)) | R3: =IF(I3="","",IF(M3<>"",YEAR(M3),IF(A3<>"",YEAR(A3),""))) | S3: =IF(I3="","",IF(M3<>"",MONTH(M3),IF(A3<>"",MONTH(A3),"")))
A4: 46280 | B4: 3 | C4: Esempio Srl | D4: Sostituto d'imposta | E4: Revisione testi | F4: 1000 | G4: 50 | H4: Si | I4: =IF(OR(F4<>"",G4<>""),ROUND(N(F4)+N(G4),2),"") | J4: =IF(I4="","",IF(D4="Sostituto d'imposta",ROUND(I4*Parametri!$B$2,2),0)) | K4: =IF(I4="","",IF(I4>Parametri!$B$4,"Si","No")) | L4: =IF(I4="","",I4-J4+IF(AND(K4="Si",H4="Si"),Parametri!$B$3,0)) | O4: =IF(L4="","",ROUND(L4-N(N4),2)) | P4: No | R4: =IF(I4="","",IF(M4<>"",YEAR(M4),IF(A4<>"",YEAR(A4),""))) | S4: =IF(I4="","",IF(M4<>"",MONTH(M4),IF(A4<>"",MONTH(A4),"")))
I5: =IF(OR(F5<>"",G5<>""),ROUND(N(F5)+N(G5),2),"") | J5: =IF(I5="","",IF(D5="Sostituto d'imposta",ROUND(I5*Parametri!$B$2,2),0)) | K5: =IF(I5="","",IF(I5>Parametri!$B$4,"Si","No")) | L5: =IF(I5="","",I5-J5+IF(AND(K5="Si",H5="Si"),Parametri!$B$3,0)) | O5: =IF(L5="","",ROUND(L5-N(N5),2)) | R5: =IF(I5="","",IF(M5<>"",YEAR(M5),IF(A5<>"",YEAR(A5),""))) | S5: =IF(I5="","",IF(M5<>"",MONTH(M5),IF(A5<>"",MONTH(A5),"")))
I6: =IF(OR(F6<>"",G6<>""),ROUND(N(F6)+N(G6),2),"") | J6: =IF(I6="","",IF(D6="Sostituto d'imposta",ROUND(I6*Parametri!$B$2,2),0)) | K6: =IF(I6="","",IF(I6>Parametri!$B$4,"Si","No")) | L6: =IF(I6="","",I6-J6+IF(AND(K6="Si",H6="Si"),Parametri!$B$3,0)) | O6: =IF(L6="","",ROUND(L6-N(N6),2)) | R6: =IF(I6="","",IF(M6<>"",YEAR(M6),IF(A6<>"",YEAR(A6),""))) | S6: =IF(I6="","",IF(M6<>"",MONTH(M6),IF(A6<>"",MONTH(A6),"")))
I7: =IF(OR(F7<>"",G7<>""),ROUND(N(F7)+N(G7),2),"") | J7: =IF(I7="","",IF(D7="Sostituto d'imposta",ROUND(I7*Parametri!$B$2,2),0)) | K7: =IF(I7="","",IF(I7>Parametri!$B$4,"Si","No")) | L7: =IF(I7="","",I7-J7+IF(AND(K7="Si",H7="Si"),Parametri!$B$3,0)) | O7: =IF(L7="","",ROUND(L7-N(N7),2)) | R7: =IF(I7="","",IF(M7<>"",YEAR(M7),IF(A7<>"",YEAR(A7),""))) | S7: =IF(I7="","",IF(M7<>"",MONTH(M7),IF(A7<>"",MONTH(A7),"")))
I8: =IF(OR(F8<>"",G8<>""),ROUND(N(F8)+N(G8),2),"") | J8: =IF(I8="","",IF(D8="Sostituto d'imposta",ROUND(I8*Parametri!$B$2,2),0)) | K8: =IF(I8="","",IF(I8>Parametri!$B$4,"Si","No")) | L8: =IF(I8="","",I8-J8+IF(AND(K8="Si",H8="Si"),Parametri!$B$3,0)) | O8: =IF(L8="","",ROUND(L8-N(N8),2)) | R8: =IF(I8="","",IF(M8<>"",YEAR(M8),IF(A8<>"",YEAR(A8),""))) | S8: =IF(I8="","",IF(M8<>"",MONTH(M8),IF(A8<>"",MONTH(A8),"")))
I9: =IF(OR(F9<>"",G9<>""),ROUND(N(F9)+N(G9),2),"") | J9: =IF(I9="","",IF(D9="Sostituto d'imposta",ROUND(I9*Parametri!$B$2,2),0)) | K9: =IF(I9="","",IF(I9>Parametri!$B$4,"Si","No")) | L9: =IF(I9="","",I9-J9+IF(AND(K9="Si",H9="Si"),Parametri!$B$3,0)) | O9: =IF(L9="","",ROUND(L9-N(N9),2)) | R9: =IF(I9="","",IF(M9<>"",YEAR(M9),IF(A9<>"",YEAR(A9),""))) | S9: =IF(I9="","",IF(M9<>"",MONTH(M9),IF(A9<>"",MONTH(A9),"")))
I10: =IF(OR(F10<>"",G10<>""),ROUND(N(F10)+N(G10),2),"") | J10: =IF(I10="","",IF(D10="Sostituto d'imposta",ROUND(I10*Parametri!$B$2,2),0)) | K10: =IF(I10="","",IF(I10>Parametri!$B$4,"Si","No")) | L10: =IF(I10="","",I10-J10+IF(AND(K10="Si",H10="Si"),Parametri!$B$3,0)) | O10: =IF(L10="","",ROUND(L10-N(N10),2)) | R10: =IF(I10="","",IF(M10<>"",YEAR(M10),IF(A10<>"",YEAR(A10),""))) | S10: =IF(I10="","",IF(M10<>"",MONTH(M10),IF(A10<>"",MONTH(A10),"")))
I11: =IF(OR(F11<>"",G11<>""),ROUND(N(F11)+N(G11),2),"") | J11: =IF(I11="","",IF(D11="Sostituto d'imposta",ROUND(I11*Parametri!$B$2,2),0)) | K11: =IF(I11="","",IF(I11>Parametri!$B$4,"Si","No")) | L11: =IF(I11="","",I11-J11+IF(AND(K11="Si",H11="Si"),Parametri!$B$3,0)) | O11: =IF(L11="","",ROUND(L11-N(N11),2)) | R11: =IF(I11="","",IF(M11<>"",YEAR(M11),IF(A11<>"",YEAR(A11),""))) | S11: =IF(I11="","",IF(M11<>"",MONTH(M11),IF(A11<>"",MONTH(A11),"")))
I12: =IF(OR(F12<>"",G12<>""),ROUND(N(F12)+N(G12),2),"") | J12: =IF(I12="","",IF(D12="Sostituto d'imposta",ROUND(I12*Parametri!$B$2,2),0)) | K12: =IF(I12="","",IF(I12>Parametri!$B$4,"Si","No")) | L12: =IF(I12="","",I12-J12+IF(AND(K12="Si",H12="Si"),Parametri!$B$3,0)) | O12: =IF(L12="","",ROUND(L12-N(N12),2)) | R12: =IF(I12="","",IF(M12<>"",YEAR(M12),IF(A12<>"",YEAR(A12),""))) | S12: =IF(I12="","",IF(M12<>"",MONTH(M12),IF(A12<>"",MONTH(A12),"")))
I13: =IF(OR(F13<>"",G13<>""),ROUND(N(F13)+N(G13),2),"") | J13: =IF(I13="","",IF(D13="Sostituto d'imposta",ROUND(I13*Parametri!$B$2,2),0)) | K13: =IF(I13="","",IF(I13>Parametri!$B$4,"Si","No")) | L13: =IF(I13="","",I13-J13+IF(AND(K13="Si",H13="Si"),Parametri!$B$3,0)) | O13: =IF(L13="","",ROUND(L13-N(N13),2)) | R13: =IF(I13="","",IF(M13<>"",YEAR(M13),IF(A13<>"",YEAR(A13),""))) | S13: =IF(I13="","",IF(M13<>"",MONTH(M13),IF(A13<>"",MONTH(A13),"")))
I14: =IF(OR(F14<>"",G14<>""),ROUND(N(F14)+N(G14),2),"") | J14: =IF(I14="","",IF(D14="Sostituto d'imposta",ROUND(I14*Parametri!$B$2,2),0)) | K14: =IF(I14="","",IF(I14>Parametri!$B$4,"Si","No")) | L14: =IF(I14="","",I14-J14+IF(AND(K14="Si",H14="Si"),Parametri!$B$3,0)) | O14: =IF(L14="","",ROUND(L14-N(N14),2)) | R14: =IF(I14="","",IF(M14<>"",YEAR(M14),IF(A14<>"",YEAR(A14),""))) | S14: =IF(I14="","",IF(M14<>"",MONTH(M14),IF(A14<>"",MONTH(A14),"")))
I15: =IF(OR(F15<>"",G15<>""),ROUND(N(F15)+N(G15),2),"") | J15: =IF(I15="","",IF(D15="Sostituto d'imposta",ROUND(I15*Parametri!$B$2,2),0)) | K15: =IF(I15="","",IF(I15>Parametri!$B$4,"Si","No")) | L15: =IF(I15="","",I15-J15+IF(AND(K15="Si",H15="Si"),Parametri!$B$3,0)) | O15: =IF(L15="","",ROUND(L15-N(N15),2)) | R15: =IF(I15="","",IF(M15<>"",YEAR(M15),IF(A15<>"",YEAR(A15),""))) | S15: =IF(I15="","",IF(M15<>"",MONTH(M15),IF(A15<>"",MONTH(A15),"")))
I16: =IF(OR(F16<>"",G16<>""),ROUND(N(F16)+N(G16),2),"") | J16: =IF(I16="","",IF(D16="Sostituto d'imposta",ROUND(I16*Parametri!$B$2,2),0)) | K16: =IF(I16="","",IF(I16>Parametri!$B$4,"Si","No")) | L16: =IF(I16="","",I16-J16+IF(AND(K16="Si",H16="Si"),Parametri!$B$3,0)) | O16: =IF(L16="","",ROUND(L16-N(N16),2)) | R16: =IF(I16="","",IF(M16<>"",YEAR(M16),IF(A16<>"",YEAR(A16),""))) | S16: =IF(I16="","",IF(M16<>"",MONTH(M16),IF(A16<>"",MONTH(A16),"")))
... I301: =IF(OR(F301<>"",G301<>""),ROUND(N(F301)+N(G301),2),"") | J301: =IF(I301="","",IF(D301="Sostituto d'imposta",ROUND(I301*Parametri!$B$2,2),0)) | K301: =IF(I301="","",IF(I301>Parametri!$B$4,"Si","No")) | L301: =IF(I301="","",I301-J301+IF(AND(K301="Si",H301="Si"),Parametri!$B$3,0)) | O301: =IF(L301="","",ROUND(L301-N(N301),2)) | R301: =IF(I301="","",IF(M301<>"",YEAR(M301),IF(A301<>"",YEAR(A301),""))) | S301: =IF(I301="","",IF(M301<>"",MONTH(M301),IF(A301<>"",MONTH(A301),"")))

Sheet Riepilogo
A1: Riepilogo annuale compensi occasionali
A2: Anno (di incasso, o della ricevuta se non ancora incassata): | B2: 2026
A4: Voce | B4: Valore
A5: Numero ricevute | B5: =COUNTIFS(Ricevute!$R$2:$R$301,$B$2)
A6: Compensi lordi (compenso + spese) € | B6: =SUMIFS(Ricevute!$I$2:$I$301,Ricevute!$R$2:$R$301,$B$2)
A7: Soglia Gestione separata INPS € | B7: =Parametri!$B$5
A8: Margine prima della soglia € | B8: =MAX(0,B7-B6)
A9: Quota della soglia usata | B9: =IF(B7>0,B6/B7,0)
A10: Stato | B10: =IF(B6>B7,"SOGLIA SUPERATA: verifica iscrizione Gestione separata INPS",IF(B9>=Parametri!$B$6,"Vicino alla soglia: pianifica i prossimi incarichi","Sotto la soglia"))
A11: Ritenute d'acconto subite € (da scomputare in dichiarazione) | B11: =SUMIFS(Ricevute!$J$2:$J$301,Ricevute!$R$2:$R$301,$B$2)
A12: Netto atteso € | B12: =SUMIFS(Ricevute!$L$2:$L$301,Ricevute!$R$2:$R$301,$B$2)
A13: Incassato € | B13: =SUMIFS(Ricevute!$N$2:$N$301,Ricevute!$R$2:$R$301,$B$2)
A14: Da incassare € | B14: =SUMIFS(Ricevute!$O$2:$O$301,Ricevute!$R$2:$R$301,$B$2)
A15: Ricevute con bollo 2 € dovuto | B15: =COUNTIFS(Ricevute!$R$2:$R$301,$B$2,Ricevute!$K$2:$K$301,"Si")
A16: Ricevute a sostituti d'imposta senza CU ricevuta | B16: =COUNTIFS(Ricevute!$R$2:$R$301,$B$2,Ricevute!$D$2:$D$301,"Sostituto d'imposta",Ricevute!$P$2:$P$301,"<>Si")
A18: Lordo e ritenute come calcolati dal registro: confrontali con le Certificazioni Uniche ricevute dai committenti, che fanno fede.
A20: Mese | B20: Lordo € | C20: Cumulato €
A21: Gen | B21: =SUMIFS(Ricevute!$I$2:$I$301,Ricevute!$R$2:$R$301,$B$2,Ricevute!$S$2:$S$301,1) | C21: =SUM($B$21:B21)
A22: Feb | B22: =SUMIFS(Ricevute!$I$2:$I$301,Ricevute!$R$2:$R$301,$B$2,Ricevute!$S$2:$S$301,2) | C22: =SUM($B$21:B22)
A23: Mar | B23: =SUMIFS(Ricevute!$I$2:$I$301,Ricevute!$R$2:$R$301,$B$2,Ricevute!$S$2:$S$301,3) | C23: =SUM($B$21:B23)
A24: Apr | B24: =SUMIFS(Ricevute!$I$2:$I$301,Ricevute!$R$2:$R$301,$B$2,Ricevute!$S$2:$S$301,4) | C24: =SUM($B$21:B24)
A25: Mag | B25: =SUMIFS(Ricevute!$I$2:$I$301,Ricevute!$R$2:$R$301,$B$2,Ricevute!$S$2:$S$301,5) | C25: =SUM($B$21:B25)
A26: Giu | B26: =SUMIFS(Ricevute!$I$2:$I$301,Ricevute!$R$2:$R$301,$B$2,Ricevute!$S$2:$S$301,6) | C26: =SUM($B$21:B26)
A27: Lug | B27: =SUMIFS(Ricevute!$I$2:$I$301,Ricevute!$R$2:$R$301,$B$2,Ricevute!$S$2:$S$301,7) | C27: =SUM($B$21:B27)
A28: Ago | B28: =SUMIFS(Ricevute!$I$2:$I$301,Ricevute!$R$2:$R$301,$B$2,Ricevute!$S$2:$S$301,8) | C28: =SUM($B$21:B28)
A29: Set | B29: =SUMIFS(Ricevute!$I$2:$I$301,Ricevute!$R$2:$R$301,$B$2,Ricevute!$S$2:$S$301,9) | C29: =SUM($B$21:B29)
A30: Ott | B30: =SUMIFS(Ricevute!$I$2:$I$301,Ricevute!$R$2:$R$301,$B$2,Ricevute!$S$2:$S$301,10) | C30: =SUM($B$21:B30)
A31: Nov | B31: =SUMIFS(Ricevute!$I$2:$I$301,Ricevute!$R$2:$R$301,$B$2,Ricevute!$S$2:$S$301,11) | C31: =SUM($B$21:B31)
A32: Dic | B32: =SUMIFS(Ricevute!$I$2:$I$301,Ricevute!$R$2:$R$301,$B$2,Ricevute!$S$2:$S$301,12) | C32: =SUM($B$21:B32)
A35: Committente (scrivi il nome come nel foglio Ricevute) | B35: Lordo € | C35: Ritenute € | D35: Da incassare €
A36: Esempio Srl | B36: =IF($A36="","",SUMIFS(Ricevute!$I$2:$I$301,Ricevute!$R$2:$R$301,$B$2,Ricevute!$C$2:$C$301,$A36)) | C36: =IF($A36="","",SUMIFS(Ricevute!$J$2:$J$301,Ricevute!$R$2:$R$301,$B$2,Ricevute!$C$2:$C$301,$A36)) | D36: =IF($A36="","",SUMIFS(Ricevute!$O$2:$O$301,Ricevute!$R$2:$R$301,$B$2,Ricevute!$C$2:$C$301,$A36))
A37: Mario Esempio | B37: =IF($A37="","",SUMIFS(Ricevute!$I$2:$I$301,Ricevute!$R$2:$R$301,$B$2,Ricevute!$C$2:$C$301,$A37)) | C37: =IF($A37="","",SUMIFS(Ricevute!$J$2:$J$301,Ricevute!$R$2:$R$301,$B$2,Ricevute!$C$2:$C$301,$A37)) | D37: =IF($A37="","",SUMIFS(Ricevute!$O$2:$O$301,Ricevute!$R$2:$R$301,$B$2,Ricevute!$C$2:$C$301,$A37))
B38: =IF($A38="","",SUMIFS(Ricevute!$I$2:$I$301,Ricevute!$R$2:$R$301,$B$2,Ricevute!$C$2:$C$301,$A38)) | C38: =IF($A38="","",SUMIFS(Ricevute!$J$2:$J$301,Ricevute!$R$2:$R$301,$B$2,Ricevute!$C$2:$C$301,$A38)) | D38: =IF($A38="","",SUMIFS(Ricevute!$O$2:$O$301,Ricevute!$R$2:$R$301,$B$2,Ricevute!$C$2:$C$301,$A38))
B39: =IF($A39="","",SUMIFS(Ricevute!$I$2:$I$301,Ricevute!$R$2:$R$301,$B$2,Ricevute!$C$2:$C$301,$A39)) | C39: =IF($A39="","",SUMIFS(Ricevute!$J$2:$J$301,Ricevute!$R$2:$R$301,$B$2,Ricevute!$C$2:$C$301,$A39)) | D39: =IF($A39="","",SUMIFS(Ricevute!$O$2:$O$301,Ricevute!$R$2:$R$301,$B$2,Ricevute!$C$2:$C$301,$A39))
B40: =IF($A40="","",SUMIFS(Ricevute!$I$2:$I$301,Ricevute!$R$2:$R$301,$B$2,Ricevute!$C$2:$C$301,$A40)) | C40: =IF($A40="","",SUMIFS(Ricevute!$J$2:$J$301,Ricevute!$R$2:$R$301,$B$2,Ricevute!$C$2:$C$301,$A40)) | D40: =IF($A40="","",SUMIFS(Ricevute!$O$2:$O$301,Ricevute!$R$2:$R$301,$B$2,Ricevute!$C$2:$C$301,$A40))
B41: =IF($A41="","",SUMIFS(Ricevute!$I$2:$I$301,Ricevute!$R$2:$R$301,$B$2,Ricevute!$C$2:$C$301,$A41)) | C41: =IF($A41="","",SUMIFS(Ricevute!$J$2:$J$301,Ricevute!$R$2:$R$301,$B$2,Ricevute!$C$2:$C$301,$A41)) | D41: =IF($A41="","",SUMIFS(Ricevute!$O$2:$O$301,Ricevute!$R$2:$R$301,$B$2,Ricevute!$C$2:$C$301,$A41))
B42: =IF($A42="","",SUMIFS(Ricevute!$I$2:$I$301,Ricevute!$R$2:$R$301,$B$2,Ricevute!$C$2:$C$301,$A42)) | C42: =IF($A42="","",SUMIFS(Ricevute!$J$2:$J$301,Ricevute!$R$2:$R$301,$B$2,Ricevute!$C$2:$C$301,$A42)) | D42: =IF($A42="","",SUMIFS(Ricevute!$O$2:$O$301,Ricevute!$R$2:$R$301,$B$2,Ricevute!$C$2:$C$301,$A42))
B43: =IF($A43="","",SUMIFS(Ricevute!$I$2:$I$301,Ricevute!$R$2:$R$301,$B$2,Ricevute!$C$2:$C$301,$A43)) | C43: =IF($A43="","",SUMIFS(Ricevute!$J$2:$J$301,Ricevute!$R$2:$R$301,$B$2,Ricevute!$C$2:$C$301,$A43)) | D43: =IF($A43="","",SUMIFS(Ricevute!$O$2:$O$301,Ricevute!$R$2:$R$301,$B$2,Ricevute!$C$2:$C$301,$A43))
B44: =IF($A44="","",SUMIFS(Ricevute!$I$2:$I$301,Ricevute!$R$2:$R$301,$B$2,Ricevute!$C$2:$C$301,$A44)) | C44: =IF($A44="","",SUMIFS(Ricevute!$J$2:$J$301,Ricevute!$R$2:$R$301,$B$2,Ricevute!$C$2:$C$301,$A44)) | D44: =IF($A44="","",SUMIFS(Ricevute!$O$2:$O$301,Ricevute!$R$2:$R$301,$B$2,Ricevute!$C$2:$C$301,$A44))
B45: =IF($A45="","",SUMIFS(Ricevute!$I$2:$I$301,Ricevute!$R$2:$R$301,$B$2,Ricevute!$C$2:$C$301,$A45)) | C45: =IF($A45="","",SUMIFS(Ricevute!$J$2:$J$301,Ricevute!$R$2:$R$301,$B$2,Ricevute!$C$2:$C$301,$A45)) | D45: =IF($A45="","",SUMIFS(Ricevute!$O$2:$O$301,Ricevute!$R$2:$R$301,$B$2,Ricevute!$C$2:$C$301,$A45))
...

Sheet Parametri
A1: Parametro | B1: Valore | C1: Fonte
A2: Aliquota ritenuta d'acconto | B2: 0.2 | C2: art. 25 DPR 600/1973; dal 1/1/2027 art. 38, c. 1, D.Lgs. 33/2025 (20%) — verificato 31/10/2026
A3: Imposta di bollo € | B3: 2 | C3: DPR 642/1972, Tariffa all. A, parte I, art. 13 (riferimento dal 2027 da verificare)
A4: Bollo dovuto se importo superiore a € | B4: 77.47 | C4: DPR 642/1972, Tariffa all. A, parte I, art. 13, nota 2
A5: Soglia annua Gestione separata INPS € | B5: 5000 | C5: art. 44, comma 2, DL 269/2003
A6: Avviso quando superi questa quota della soglia | B6: 0.8 | C6: scelta dell'utente (non normativa)
